<?xml version="1.0" encoding="utf-8"?>
<!-- This URDF was automatically created by SolidWorks to URDF Exporter! Originally created by Stephen Brawner (brawner@gmail.com) 
     Commit Version: 1.6.0-4-g7f85cfe  Build Version: 1.6.7995.38578
     For more information, please see http://wiki.ros.org/sw_urdf_exporter -->
<robot
  name="gripper_end_effector">
  <link
    name="base_link">
    <inertial>
      <origin
        xyz="-0.038799 0.039037 -5.6771E-08"
        rpy="0 0 0" />
      <mass
        value="4.037" />
      <inertia
        ixx="0.0047485"
        ixy="2.5452E-06"
        ixz="-6.9936E-08"
        iyy="0.015979"
        iyz="4.4737E-10"
        izz="0.01214" />
    </inertial>
    <visual>
      <origin
        xyz="0 0 0"
        rpy="0 0 0" />
      <geometry>
        <mesh
          filename="package://gripper_end_effector/meshes/base_link.STL" />
      </geometry>
      <material
        name="">
        <color
          rgba="0.75294 0.75294 0.75294 1" />
      </material>
    </visual>
    <collision>
      <origin
        xyz="0 0 0"
        rpy="0 0 0" />
      <geometry>
        <mesh
          filename="package://gripper_end_effector/meshes/base_link.STL" />
      </geometry>
    </collision>
  </link>
  <link
    name="j2">
    <inertial>
      <origin
        xyz="-0.021245 4.8231E-05 -0.10539"
        rpy="0 0 0" />
      <mass
        value="0.97731" />
      <inertia
        ixx="0.00070562"
        ixy="-1.9214E-07"
        ixz="2.8678E-06"
        iyy="0.00051951"
        iyz="3.1462E-07"
        izz="0.00067989" />
    </inertial>
    <visual>
      <origin
        xyz="0 0 0"
        rpy="0 0 0" />
      <geometry>
        <mesh
          filename="package://gripper_end_effector/meshes/j2.STL" />
      </geometry>
      <material
        name="">
        <color
          rgba="0.75294 0.75294 0.75294 1" />
      </material>
    </visual>
    <collision>
      <origin
        xyz="0 0 0"
        rpy="0 0 0" />
      <geometry>
        <mesh
          filename="package://gripper_end_effector/meshes/j2.STL" />
      </geometry>
    </collision>
  </link>
  <joint
    name="j2"
    type="revolute">
    <origin
      xyz="0 0 0"
      rpy="3.1416 0 1.5708" />
    <parent
      link="base_link" />
    <child
      link="j2" />
    <axis
      xyz="0 0 1" />
    <limit
      lower="-1.57"
      upper="1.57"
      effort="50"
      velocity="10" />
  </joint>
  <link
    name="j3">
    <inertial>
      <origin
        xyz="0.04398 -5.3597E-05 -0.12806"
        rpy="0 0 0" />
      <mass
        value="0.68518" />
      <inertia
        ixx="0.0044141"
        ixy="-4.0767E-08"
        ixz="-1.4274E-05"
        iyy="0.004191"
        iyz="-9.0894E-07"
        izz="0.0003341" />
    </inertial>
    <visual>
      <origin
        xyz="0 0 0"
        rpy="0 0 0" />
      <geometry>
        <mesh
          filename="package://gripper_end_effector/meshes/j3.STL" />
      </geometry>
      <material
        name="">
        <color
          rgba="0.75294 0.75294 0.75294 1" />
      </material>
    </visual>
    <collision>
      <origin
        xyz="0 0 0"
        rpy="0 0 0" />
      <geometry>
        <mesh
          filename="package://gripper_end_effector/meshes/j3.STL" />
      </geometry>
    </collision>
  </link>
  <joint
    name="j3"
    type="revolute">
    <origin
      xyz="0 0 -0.1385"
      rpy="0 0 0" />
    <parent
      link="j2" />
    <child
      link="j3" />
    <axis
      xyz="1 0 0" />
    <limit
      lower="-1.57"
      upper="1.57"
      effort="50"
      velocity="10" />
  </joint>
  <link
    name="j4">
    <inertial>
      <origin
        xyz="0.015213 -0.035076 1.974E-06"
        rpy="0 0 0" />
      <mass
        value="0.23302" />
      <inertia
        ixx="7.0267E-05"
        ixy="1.3165E-09"
        ixz="2.8292E-14"
        iyy="6.7939E-05"
        iyz="8.3323E-14"
        izz="6.51E-05" />
    </inertial>
    <visual>
      <origin
        xyz="0 0 0"
        rpy="0 0 0" />
      <geometry>
        <mesh
          filename="package://gripper_end_effector/meshes/j4.STL" />
      </geometry>
      <material
        name="">
        <color
          rgba="0.75294 0.75294 0.75294 1" />
      </material>
    </visual>
    <collision>
      <origin
        xyz="0 0 0"
        rpy="0 0 0" />
      <geometry>
        <mesh
          filename="package://gripper_end_effector/meshes/j4.STL" />
      </geometry>
    </collision>
  </link>
  <joint
    name="j4"
    type="revolute">
    <origin
      xyz="0 0 -0.322"
      rpy="0 0 0" />
    <parent
      link="j3" />
    <child
      link="j4" />
    <axis
      xyz="1 0 0" />
    <limit
      lower="-1.57"
      upper="1.57"
      effort="50"
      velocity="10" />
  </joint>
  <link
    name="j5">
    <inertial>
      <origin
        xyz="-0.001844 0.10181 0.00027913"
        rpy="0 0 0" />
      <mass
        value="0.28259" />
      <inertia
        ixx="0.00065499"
        ixy="1.9322E-05"
        ixz="-1.3151E-06"
        iyy="0.00017713"
        iyz="8.4538E-07"
        izz="0.00074297" />
    </inertial>
    <visual>
      <origin
        xyz="0 0 0"
        rpy="0 0 0" />
      <geometry>
        <mesh
          filename="package://gripper_end_effector/meshes/j5.STL" />
      </geometry>
      <material
        name="">
        <color
          rgba="0.75294 0.75294 0.75294 1" />
      </material>
    </visual>
    <collision>
      <origin
        xyz="0 0 0"
        rpy="0 0 0" />
      <geometry>
        <mesh
          filename="package://gripper_end_effector/meshes/j5.STL" />
      </geometry>
    </collision>
  </link>
  <joint
    name="j5"
    type="revolute">
    <origin
      xyz="0 0 0"
      rpy="0 0 0" />
    <parent
      link="j4" />
    <child
      link="j5" />
    <axis
      xyz="0 1 0" />
    <limit
      lower="-1.57"
      upper="1.57"
      effort="50"
      velocity="10" />
  </joint>
  <link
    name="j6">
    <inertial>
      <origin
        xyz="-0.0013063 -0.0093348 -1.0804E-05"
        rpy="0 0 0" />
      <mass
        value="0.15216" />
      <inertia
        ixx="3.7125E-05"
        ixy="-1.2877E-06"
        ixz="5.119E-09"
        iyy="4.1674E-05"
        iyz="4.97E-08"
        izz="4.2099E-05" />
    </inertial>
    <visual>
      <origin
        xyz="0 0 0"
        rpy="0 0 0" />
      <geometry>
        <mesh
          filename="package://gripper_end_effector/meshes/j6.STL" />
      </geometry>
      <material
        name="">
        <color
          rgba="0.75294 0.75294 0.75294 1" />
      </material>
    </visual>
    <collision>
      <origin
        xyz="0 0 0"
        rpy="0 0 0" />
      <geometry>
        <mesh
          filename="package://gripper_end_effector/meshes/j6.STL" />
      </geometry>
    </collision>
  </link>
  <joint
    name="j6"
    type="revolute">
    <origin
      xyz="0 0.23275 0"
      rpy="0 0 0" />
    <parent
      link="j5" />
    <child
      link="j6" />
    <axis
      xyz="1 0 0" />
    <limit
      lower="-1.57"
      upper="1.57"
      effort="50"
      velocity="10" />
  </joint>
  <link
    name="ef">
    <inertial>
      <origin
        xyz="-6.4274E-05 0.062726 -0.0036376"
        rpy="0 0 0" />
      <mass
        value="0.167" />
      <inertia
        ixx="0.00014431"
        ixy="-1.1841E-06"
        ixz="-1.4094E-06"
        iyy="0.00016034"
        iyz="1.6608E-05"
        izz="0.00018457" />
    </inertial>
    <visual>
      <origin
        xyz="0 0 0"
        rpy="0 0 0" />
      <geometry>
        <mesh
          filename="package://gripper_end_effector/meshes/ef.STL" />
      </geometry>
      <material
        name="">
        <color
          rgba="0.75294 0.75294 0.75294 1" />
      </material>
    </visual>
    <collision>
      <origin
        xyz="0 0 0"
        rpy="0 0 0" />
      <geometry>
        <mesh
          filename="package://gripper_end_effector/meshes/ef.STL" />
      </geometry>
    </collision>
  </link>
  <joint
    name="ef"
    type="revolute">
    <origin
      xyz="0 0.02775 0"
      rpy="0 0 0" />
    <parent
      link="j6" />
    <child
      link="ef" />
    <axis
      xyz="0 1 0" />
    <limit
      lower="-1.57"
      upper="1.57"
      effort="50"
      velocity="10" />
  </joint>
</robot>